<?xml version="1.0"?>
<robot name="simple_humanoid">
  <!-- Base link - the main body of the robot -->
  <link name="base_link">
    <visual>
      <geometry>
        <box size="0.5 0.3 0.6"/>
      </geometry>
      <material name="blue">
        <color rgba="0 0 1 1"/>
      </material>
    </visual>
    <collision>
      <geometry>
        <box size="0.5 0.3 0.6"/>
      </geometry>
    </collision>
    <inertial>
      <mass value="10.0"/>
      <inertia ixx="1.0" ixy="0.0" ixz="0.0" iyy="1.0" iyz="0.0" izz="1.0"/>
    </inertial>
  </link>

  <!-- Head link -->
  <link name="head">
    <visual>
      <geometry>
        <sphere radius="0.1"/>
      </geometry>
      <material name="white">
        <color rgba="1 1 1 1"/>
      </material>
    </visual>
    <collision>
      <geometry>
        <sphere radius="0.1"/>
      </geometry>
    </collision>
    <inertial>
      <mass value="1.0"/>
      <inertia ixx="0.01" ixy="0.0" ixz="0.0" iyy="0.01" iyz="0.0" izz="0.01"/>
    </inertial>
  </link>

  <!-- Joint connecting head to base -->
  <joint name="neck_joint" type="revolute">
    <parent link="base_link"/>
    <child link="head"/>
    <origin xyz="0 0 0.4" rpy="0 0 0"/>
    <axis xyz="0 1 0"/>  <!-- Y-axis for head nodding -->
    <limit lower="-0.5" upper="0.5" effort="100" velocity="1"/>
  </joint>

  <!-- Left arm upper part -->
  <link name="left_upper_arm">
    <visual>
      <geometry>
        <cylinder length="0.3" radius="0.05"/>
      </geometry>
      <origin xyz="0 0 0.15" rpy="0 0 0"/>
      <material name="gray">
        <color rgba="0.5 0.5 0.5 1"/>
      </material>
    </visual>
    <collision>
      <geometry>
        <cylinder length="0.3" radius="0.05"/>
      </geometry>
      <origin xyz="0 0 0.15" rpy="0 0 0"/>
    </collision>
    <inertial>
      <mass value="1.0"/>
      <inertia ixx="0.01" ixy="0.0" ixz="0.0" iyy="0.01" iyz="0.0" izz="0.01"/>
    </inertial>
  </link>

  <!-- Joint connecting left arm to base -->
  <joint name="left_shoulder_joint" type="revolute">
    <parent link="base_link"/>
    <child link="left_upper_arm"/>
    <origin xyz="0.15 0.2 0.2" rpy="0 0 0"/>
    <axis xyz="0 1 0"/>  <!-- Y-axis for shoulder movement -->
    <limit lower="-1.57" upper="1.57" effort="50" velocity="2"/>
  </joint>

  <!-- Right arm upper part -->
  <link name="right_upper_arm">
    <visual>
      <geometry>
        <cylinder length="0.3" radius="0.05"/>
      </geometry>
      <origin xyz="0 0 0.15" rpy="0 0 0"/>
      <material name="gray">
        <color rgba="0.5 0.5 0.5 1"/>
      </material>
    </visual>
    <collision>
      <geometry>
        <cylinder length="0.3" radius="0.05"/>
      </geometry>
      <origin xyz="0 0 0.15" rpy="0 0 0"/>
    </collision>
    <inertial>
      <mass value="1.0"/>
      <inertia ixx="0.01" ixy="0.0" ixz="0.0" iyy="0.01" iyz="0.0" izz="0.01"/>
    </inertial>
  </link>

  <!-- Joint connecting right arm to base -->
  <joint name="right_shoulder_joint" type="revolute">
    <parent link="base_link"/>
    <child link="right_upper_arm"/>
    <origin xyz="0.15 -0.2 0.2" rpy="0 0 0"/>
    <axis xyz="0 1 0"/>  <!-- Y-axis for shoulder movement -->
    <limit lower="-1.57" upper="1.57" effort="50" velocity="2"/>
  </joint>

  <!-- Left leg upper part -->
  <link name="left_thigh">
    <visual>
      <geometry>
        <cylinder length="0.4" radius="0.06"/>
      </geometry>
      <origin xyz="0 0 -0.2" rpy="0 0 0"/>
      <material name="dark_gray">
        <color rgba="0.3 0.3 0.3 1"/>
      </material>
    </visual>
    <collision>
      <geometry>
        <cylinder length="0.4" radius="0.06"/>
      </geometry>
      <origin xyz="0 0 -0.2" rpy="0 0 0"/>
    </collision>
    <inertial>
      <mass value="2.0"/>
      <inertia ixx="0.02" ixy="0.0" ixz="0.0" iyy="0.02" iyz="0.0" izz="0.02"/>
    </inertial>
  </link>

  <!-- Joint connecting left leg to base -->
  <joint name="left_hip_joint" type="revolute">
    <parent link="base_link"/>
    <child link="left_thigh"/>
    <origin xyz="-0.1 -0.1 -0.3" rpy="0 0 0"/>
    <axis xyz="0 1 0"/>
    <limit lower="-0.5" upper="0.5" effort="100" velocity="1"/>
  </joint>

  <!-- Right leg upper part -->
  <link name="right_thigh">
    <visual>
      <geometry>
        <cylinder length="0.4" radius="0.06"/>
      </geometry>
      <origin xyz="0 0 -0.2" rpy="0 0 0"/>
      <material name="dark_gray">
        <color rgba="0.3 0.3 0.3 1"/>
      </material>
    </visual>
    <collision>
      <geometry>
        <cylinder length="0.4" radius="0.06"/>
      </geometry>
      <origin xyz="0 0 -0.2" rpy="0 0 0"/>
    </collision>
    <inertial>
      <mass value="2.0"/>
      <inertia ixx="0.02" ixy="0.0" ixz="0.0" iyy="0.02" iyz="0.0" izz="0.02"/>
    </inertial>
  </link>

  <!-- Joint connecting right leg to base -->
  <joint name="right_hip_joint" type="revolute">
    <parent link="base_link"/>
    <child link="right_thigh"/>
    <origin xyz="-0.1 0.1 -0.3" rpy="0 0 0"/>
    <axis xyz="0 1 0"/>
    <limit lower="-0.5" upper="0.5" effort="100" velocity="1"/>
  </joint>
</robot>