<?xml version="1.0" ?>
<sdf version="1.7">
  <world name="humanoid_simple_world">
    <!-- Physics configuration -->
    <physics name="default_physics" type="ode">
      <max_step_size>0.001</max_step_size>
      <real_time_factor>1.0</real_time_factor>
      <real_time_update_rate>1000.0</real_time_update_rate>
      <gravity>0 0 -9.8</gravity>
      <ode>
        <solver>
          <type>quick</type>
          <iters>100</iters>
          <sor>1.3</sor>
        </solver>
        <constraints>
          <cfm>0.000001</cfm>
          <erp>0.2</erp>
          <contact_max_correcting_vel>100.0</contact_max_correcting_vel>
          <contact_surface_layer>0.001</contact_surface_layer>
        </constraints>
      </ode>
    </physics>

    <!-- Lighting -->
    <light name="sun" type="directional">
      <cast_shadows>true</cast_shadows>
      <pose>0 0 10 0 0 0</pose>
      <diffuse>0.8 0.8 0.8 1</diffuse>
      <specular>0.2 0.2 0.2 1</specular>
      <attenuation>
        <range>1000</range>
        <constant>0.9</constant>
        <linear>0.01</linear>
        <quadratic>0.001</quadratic>
      </attenuation>
      <direction>-0.4 0.2 -1</direction>
    </light>

    <!-- Ground plane -->
    <model name="ground_plane">
      <static>true</static>
      <link name="link">
        <collision name="collision">
          <geometry>
            <plane>
              <normal>0 0 1</normal>
              <size>100 100</size>
            </plane>
          </geometry>
          <surface>
            <friction>
              <ode>
                <mu>0.8</mu>
                <mu2>0.8</mu2>
              </ode>
            </friction>
          </surface>
        </collision>
        <visual name="visual">
          <geometry>
            <plane>
              <normal>0 0 1</normal>
              <size>100 100</size>
            </plane>
          </geometry>
          <material>
            <ambient>0.7 0.7 0.7 1</ambient>
            <diffuse>0.7 0.7 0.7 1</diffuse>
            <specular>0.0 0.0 0.0 1</specular>
          </material>
        </visual>
      </link>
    </model>

    <!-- Simple humanoid robot -->
    <model name="simple_humanoid">
      <pose>0 0 1 0 0 0</pose>

      <!-- Base/torso link -->
      <link name="base_link">
        <pose>0 0 0.3 0 0 0</pose>
        <inertial>
          <mass>10.0</mass>
          <inertia>
            <ixx>0.5</ixx>
            <ixy>0.0</ixy>
            <ixz>0.0</ixz>
            <iyy>0.5</iyy>
            <iyz>0.0</iyz>
            <izz>0.3</izz>
          </inertia>
        </inertial>
        <visual name="visual">
          <geometry>
            <box>
              <size>0.3 0.2 0.6</size>
            </box>
          </geometry>
          <material>
            <ambient>0 0 1 1</ambient>
            <diffuse>0 0 1 1</diffuse>
          </material>
        </visual>
        <collision name="collision">
          <geometry>
            <box>
              <size>0.3 0.2 0.6</size>
            </box>
          </geometry>
        </collision>
      </link>

      <!-- Head -->
      <link name="head">
        <pose>0 0 0.4 0 0 0</pose>
        <inertial>
          <mass>2.0</mass>
          <inertia>
            <ixx>0.02</ixx>
            <ixy>0.0</ixy>
            <ixz>0.0</ixz>
            <iyy>0.02</iyy>
            <iyz>0.0</iyz>
            <izz>0.02</izz>
          </inertia>
        </inertial>
        <visual name="visual">
          <geometry>
            <sphere>
              <radius>0.1</radius>
            </sphere>
          </geometry>
          <material>
            <ambient>1 1 1 1</ambient>
            <diffuse>1 1 1 1</diffuse>
          </material>
        </visual>
        <collision name="collision">
          <geometry>
            <sphere>
              <radius>0.1</radius>
            </sphere>
          </geometry>
        </collision>
      </link>

      <joint name="neck_joint" type="revolute">
        <parent>base_link</parent>
        <child>head</child>
        <axis>
          <xyz>0 1 0</xyz>
          <limit>
            <lower>-0.5</lower>
            <upper>0.5</upper>
            <effort>10.0</effort>
            <velocity>2.0</velocity>
          </limit>
        </axis>
        <pose>0 0 0.3 0 0 0</pose>
      </joint>

      <!-- Left leg -->
      <link name="left_thigh">
        <pose>-0.05 -0.1 -0.1 0 0 0</pose>
        <inertial>
          <mass>3.0</mass>
          <inertia>
            <ixx>0.08</ixx>
            <ixy>0.0</ixy>
            <ixz>0.01</ixz>
            <iyy>0.08</iyy>
            <iyz>0.0</iyz>
            <izz>0.01</izz>
          </inertia>
        </inertial>
        <visual name="visual">
          <geometry>
            <cylinder>
              <length>0.3</length>
              <radius>0.06</radius>
            </cylinder>
          </geometry>
          <pose>0 0 -0.15 1.5708 0 0</pose>
          <material>
            <ambient>0.5 0.5 0.5 1</ambient>
            <diffuse>0.5 0.5 0.5 1</diffuse>
          </material>
        </visual>
        <collision name="collision">
          <geometry>
            <cylinder>
              <length>0.3</length>
              <radius>0.06</radius>
            </cylinder>
          </geometry>
          <pose>0 0 -0.15 1.5708 0 0</pose>
        </collision>
      </link>

      <joint name="left_hip_joint" type="revolute">
        <parent>base_link</parent>
        <child>left_thigh</child>
        <axis>
          <xyz>0 1 0</xyz>
          <limit>
            <lower>-1.0</lower>
            <upper>0.5</upper>
            <effort>50.0</effort>
            <velocity>5.0</velocity>
          </limit>
        </axis>
        <pose>-0.05 -0.1 0 0 0 0</pose>
      </joint>

      <link name="left_shin">
        <pose>-0.05 -0.1 -0.4 0 0 0</pose>
        <inertial>
          <mass>2.0</mass>
          <inertia>
            <ixx>0.04</ixx>
            <ixy>0.0</ixy>
            <ixz>0.005</ixz>
            <iyy>0.04</iyy>
            <iyz>0.0</iyz>
            <izz>0.008</izz>
          </inertia>
        </inertial>
        <visual name="visual">
          <geometry>
            <cylinder>
              <length>0.24</length>
              <radius>0.05</radius>
            </cylinder>
          </geometry>
          <pose>0 0 -0.12 1.5708 0 0</pose>
          <material>
            <ambient>0.5 0.5 0.5 1</ambient>
            <diffuse>0.5 0.5 0.5 1</diffuse>
          </material>
        </visual>
        <collision name="collision">
          <geometry>
            <cylinder>
              <length>0.24</length>
              <radius>0.05</radius>
            </cylinder>
          </geometry>
          <pose>0 0 -0.12 1.5708 0 0</pose>
        </collision>
      </link>

      <joint name="left_knee_joint" type="revolute">
        <parent>left_thigh</parent>
        <child>left_shin</child>
        <axis>
          <xyz>0 1 0</xyz>
          <limit>
            <lower>0.0</lower>
            <upper>2.0</upper>
            <effort>40.0</effort>
            <velocity>4.0</velocity>
          </limit>
        </axis>
        <pose>0 0 -0.3 0 0 0</pose>
      </joint>

      <link name="left_foot">
        <pose>-0.05 -0.1 -0.64 0 0 0</pose>
        <inertial>
          <mass>1.0</mass>
          <inertia>
            <ixx>0.01</ixx>
            <ixy>0.0</ixy>
            <ixz>0.001</ixz>
            <iyy>0.02</iyy>
            <iyz>0.0</iyz>
            <izz>0.015</izz>
          </inertia>
        </inertial>
        <visual name="visual">
          <geometry>
            <box>
              <size>0.18 0.1 0.06</size>
            </box>
          </geometry>
          <material>
            <ambient>0.3 0.3 0.3 1</ambient>
            <diffuse>0.3 0.3 0.3 1</diffuse>
          </material>
        </visual>
        <collision name="collision">
          <geometry>
            <box>
              <size>0.18 0.1 0.06</size>
            </box>
          </geometry>
        </collision>
      </link>

      <joint name="left_ankle_joint" type="revolute">
        <parent>left_shin</parent>
        <child>left_foot</child>
        <axis>
          <xyz>0 1 0</xyz>
          <limit>
            <lower>-0.5</lower>
            <upper>0.5</upper>
            <effort>20.0</effort>
            <velocity>3.0</velocity>
          </limit>
        </axis>
        <pose>0 0 -0.24 0 0 0</pose>
      </joint>

      <!-- Right leg (similar to left but mirrored) -->
      <link name="right_thigh">
        <pose>-0.05 0.1 -0.1 0 0 0</pose>
        <inertial>
          <mass>3.0</mass>
          <inertia>
            <ixx>0.08</ixx>
            <ixy>0.0</ixy>
            <ixz>0.01</ixz>
            <iyy>0.08</iyy>
            <iyz>0.0</iyz>
            <izz>0.01</izz>
          </inertia>
        </inertial>
        <visual name="visual">
          <geometry>
            <cylinder>
              <length>0.3</length>
              <radius>0.06</radius>
            </cylinder>
          </geometry>
          <pose>0 0 -0.15 1.5708 0 0</pose>
          <material>
            <ambient>0.5 0.5 0.5 1</ambient>
            <diffuse>0.5 0.5 0.5 1</diffuse>
          </material>
        </visual>
        <collision name="collision">
          <geometry>
            <cylinder>
              <length>0.3</length>
              <radius>0.06</radius>
            </cylinder>
          </geometry>
          <pose>0 0 -0.15 1.5708 0 0</pose>
        </collision>
      </link>

      <joint name="right_hip_joint" type="revolute">
        <parent>base_link</parent>
        <child>right_thigh</child>
        <axis>
          <xyz>0 1 0</xyz>
          <limit>
            <lower>-1.0</lower>
            <upper>0.5</upper>
            <effort>50.0</effort>
            <velocity>5.0</velocity>
          </limit>
        </axis>
        <pose>-0.05 0.1 0 0 0 0</pose>
      </joint>

      <link name="right_shin">
        <pose>-0.05 0.1 -0.4 0 0 0</pose>
        <inertial>
          <mass>2.0</mass>
          <inertia>
            <ixx>0.04</ixx>
            <ixy>0.0</ixy>
            <ixz>0.005</ixz>
            <iyy>0.04</iyy>
            <iyz>0.0</iyz>
            <izz>0.008</izz>
          </inertia>
        </inertial>
        <visual name="visual">
          <geometry>
            <cylinder>
              <length>0.24</length>
              <radius>0.05</radius>
            </cylinder>
          </geometry>
          <pose>0 0 -0.12 1.5708 0 0</pose>
          <material>
            <ambient>0.5 0.5 0.5 1</ambient>
            <diffuse>0.5 0.5 0.5 1</diffuse>
          </material>
        </visual>
        <collision name="collision">
          <geometry>
            <cylinder>
              <length>0.24</length>
              <radius>0.05</radius>
            </cylinder>
          </geometry>
          <pose>0 0 -0.12 1.5708 0 0</pose>
        </collision>
      </link>

      <joint name="right_knee_joint" type="revolute">
        <parent>right_thigh</parent>
        <child>right_shin</child>
        <axis>
          <xyz>0 1 0</xyz>
          <limit>
            <lower>0.0</lower>
            <upper>2.0</upper>
            <effort>40.0</effort>
            <velocity>4.0</velocity>
          </limit>
        </axis>
        <pose>0 0 -0.3 0 0 0</pose>
      </joint>

      <link name="right_foot">
        <pose>-0.05 0.1 -0.64 0 0 0</pose>
        <inertial>
          <mass>1.0</mass>
          <inertia>
            <ixx>0.01</ixx>
            <ixy>0.0</ixy>
            <ixz>0.001</ixz>
            <iyy>0.02</iyy>
            <iyz>0.0</iyz>
            <izz>0.015</izz>
          </inertia>
        </inertial>
        <visual name="visual">
          <geometry>
            <box>
              <size>0.18 0.1 0.06</size>
            </box>
          </geometry>
          <material>
            <ambient>0.3 0.3 0.3 1</ambient>
            <diffuse>0.3 0.3 0.3 1</diffuse>
          </material>
        </visual>
        <collision name="collision">
          <geometry>
            <box>
              <size>0.18 0.1 0.06</size>
            </box>
          </geometry>
        </collision>
      </link>

      <joint name="right_ankle_joint" type="revolute">
        <parent>right_shin</parent>
        <child>right_foot</child>
        <axis>
          <xyz>0 1 0</xyz>
          <limit>
            <lower>-0.5</lower>
            <upper>0.5</upper>
            <effort>20.0</effort>
            <velocity>3.0</velocity>
          </limit>
        </axis>
        <pose>0 0 -0.24 0 0 0</pose>
      </joint>
    </model>

    <!-- Additional objects for testing -->
    <model name="test_box">
      <pose>2 0 0.5 0 0 0</pose>
      <link name="link">
        <inertial>
          <mass>1.0</mass>
          <inertia>
            <ixx>0.083</ixx>
            <ixy>0</ixy>
            <ixz>0</ixz>
            <iyy>0.083</iyy>
            <iyz>0</iyz>
            <izz>0.083</izz>
          </inertia>
        </inertial>
        <visual name="visual">
          <geometry>
            <box>
              <size>0.5 0.5 1.0</size>
            </box>
          </geometry>
          <material>
            <ambient>0.8 0.4 0.0 1</ambient>
            <diffuse>0.8 0.4 0.0 1</diffuse>
          </material>
        </visual>
        <collision name="collision">
          <geometry>
            <box>
              <size>0.5 0.5 1.0</size>
            </box>
          </geometry>
        </collision>
      </link>
    </model>
  </world>
</sdf>